<?xml version="1.0" ?>
<robot name="rs_robot" version="1.0">
  <joint name="base_link_joint" type="fixed">
    <origin rpy="0.00000 0.00000 0.00000" xyz="0.00000 0.00000 0.00000"/>
    <parent link="base_footprint"/>
    <child link="base_link"/>
  </joint>
  <joint name="fl_steering_joint" type="revolute">
    <limit lower="-2.10000" upper="2.10000" effort="5" velocity="6.28000"/>
    <origin rpy="0.00000 0.00000 0.00000" xyz="0.07700 0.03100 -0.00400"/>
    <parent link="base_link"/>
    <child link="fl_steering_link"/>
    <axis xyz="0.00000 0.00000 1.00000"/>
  </joint>
  <joint name="fl_wheel_joint" type="continuous">
    <limit lower="0.00000" upper="0.00000" effort="1.50000" velocity="20"/>
    <origin rpy="0.00000 0.00000 -3.14159" xyz="0.00000 0.02100 -0.02500"/>
    <parent link="fl_steering_link"/>
    <child link="fl_wheel_link"/>
    <axis xyz="0.00000 -1.00000 0.00000"/>
  </joint>
  <joint name="fr_steering_joint" type="revolute">
    <limit lower="-2.10000" upper="2.10000" effort="5" velocity="6.28000"/>
    <origin rpy="0.00000 0.00000 0.00000" xyz="0.07700 -0.03100 -0.00400"/>
    <parent link="base_link"/>
    <child link="fr_steering_link"/>
    <axis xyz="0.00000 0.00000 1.00000"/>
  </joint>
  <joint name="fr_wheel_joint" type="continuous">
    <limit lower="0.00000" upper="0.00000" effort="1.50000" velocity="20"/>
    <origin rpy="0.00000 0.00000 0.00000" xyz="0.00000 -0.02100 -0.02500"/>
    <parent link="fr_steering_link"/>
    <child link="fr_wheel_link"/>
    <axis xyz="0.00000 1.00000 0.00000"/>
  </joint>
  <joint name="rl_steering_joint" type="revolute">
    <limit lower="-2.10000" upper="2.10000" effort="5" velocity="6.28000"/>
    <origin rpy="0.00000 0.00000 0.00000" xyz="-0.07700 0.03100 -0.00400"/>
    <parent link="base_link"/>
    <child link="rl_steering_link"/>
    <axis xyz="0.00000 0.00000 1.00000"/>
  </joint>
  <joint name="rl_wheel_joint" type="continuous">
    <limit lower="0.00000" upper="0.00000" effort="1.50000" velocity="20"/>
    <origin rpy="0.00000 0.00000 -3.14159" xyz="0.00000 0.02100 -0.02500"/>
    <parent link="rl_steering_link"/>
    <child link="rl_wheel_link"/>
    <axis xyz="0.00000 -1.00000 0.00000"/>
  </joint>
  <joint name="rr_steering_joint" type="revolute">
    <limit lower="-2.10000" upper="2.10000" effort="5" velocity="6.28000"/>
    <origin rpy="0.00000 0.00000 0.00000" xyz="-0.07700 -0.03100 -0.00400"/>
    <parent link="base_link"/>
    <child link="rr_steering_link"/>
    <axis xyz="0.00000 0.00000 1.00000"/>
  </joint>
  <joint name="rr_wheel_joint" type="continuous">
    <limit lower="0.00000" upper="0.00000" effort="1.50000" velocity="20"/>
    <origin rpy="0.00000 0.00000 0.00000" xyz="0.00000 -0.02100 -0.02500"/>
    <parent link="rr_steering_link"/>
    <child link="rr_wheel_link"/>
    <axis xyz="0.00000 1.00000 0.00000"/>
  </joint>
  <link name="base_footprint"/>
  <link name="base_link">
    <collision name="base_link_collision">
      <origin rpy="0.00000 0.00000 1.57775" xyz="0.00000 0.00000 0.00000"/>
      <geometry>
        <mesh filename="package://rs_robot_pkg2/meshes/stl/base_link.001.stl" scale="1.00000 1.00000 1.00000"/>
      </geometry>
    </collision>
    <inertial>
      <inertia ixx="0.00019" ixy="0.00000" ixz="0.00000" iyy="0.00006" iyz="0.00000" izz="0.00023"/>
      <origin rpy="0.00000 0.00000 0.00000" xyz="0.00000 0.00000 0.01700"/>
      <mass value="1.20000"/>
    </inertial>
    <visual name="base_link_visual">
      <origin rpy="0.00000 0.00000 0.00000" xyz="0.00000 0.00000 0.00000"/>
      <material name="Material.001"/>
      <geometry>
        <mesh filename="package://rs_robot_pkg2/meshes/stl/base_link.stl" scale="1.00000 1.00000 1.00000"/>
      </geometry>
    </visual>
  </link>
  <link name="fl_steering_link">
    <collision name="fl_steering_link_collision">
      <origin rpy="0.00000 0.00000 0.00000" xyz="0.00000 0.00000 0.00000"/>
      <geometry>
        <mesh filename="package://rs_robot_pkg2/meshes/stl/sus_link.stl" scale="1.00000 1.00000 1.00000"/>
      </geometry>
    </collision>
    <inertial>
      <inertia ixx="0.00001" ixy="0.00000" ixz="0.00000" iyy="0.00001" iyz="0.00000" izz="0.00000"/>
      <origin rpy="0.00000 0.00000 0.00000" xyz="0.00000 0.00000 -0.02000"/>
      <mass value="0.15000"/>
    </inertial>
    <visual name="fl_steering_link_visual">
      <origin rpy="0.00000 0.00000 0.00000" xyz="0.00000 0.00000 0.00000"/>
      <material name="Material.009"/>
      <geometry>
        <mesh filename="package://rs_robot_pkg2/meshes/stl/front_left_link.stl" scale="1.00000 1.00000 1.00000"/>
      </geometry>
    </visual>
  </link>
  <link name="fl_wheel_link">
    <collision name="fl_wheel_link_collision">
      <origin rpy="0.00000 0.00000 -0.00000" xyz="0.00000 0.00000 0.00000"/>
      <geometry>
        <mesh filename="package://rs_robot_pkg2/meshes/stl/robot_wheel.stl" scale="1.00000 1.00000 1.00000"/>
      </geometry>
    </collision>
    <inertial>
      <inertia ixx="0.00001" ixy="0.00000" ixz="0.00000" iyy="0.00002" iyz="0.00000" izz="0.00001"/>
      <origin rpy="0.00000 0.00000 0.00000" xyz="0.00000 -0.00700 0.00000"/>
      <mass value="0.05000"/>
    </inertial>
    <visual name="fl_wheel_link_visual">
      <origin rpy="0.00000 0.00000 -0.00000" xyz="0.00000 0.00000 0.00000"/>
      <material name="Material.018"/>
      <geometry>
        <mesh filename="package://rs_robot_pkg2/meshes/stl/wheel_link.stl" scale="1.00000 1.00000 1.00000"/>
      </geometry>
    </visual>
  </link>
  <link name="fr_steering_link">
    <collision name="fr_steering_link_collision">
      <origin rpy="0.00000 0.00000 0.00000" xyz="0.00000 0.00000 0.00000"/>
      <geometry>
        <mesh filename="package://rs_robot_pkg2/meshes/stl/sus_link.stl" scale="1.00000 1.00000 1.00000"/>
      </geometry>
    </collision>
    <inertial>
      <inertia ixx="0.00001" ixy="0.00000" ixz="0.00000" iyy="0.00001" iyz="0.00000" izz="0.00000"/>
      <origin rpy="0.00000 0.00000 0.00000" xyz="0.00000 0.00000 -0.02000"/>
      <mass value="0.15000"/>
    </inertial>
    <visual name="fr_steering_link_visual">
      <origin rpy="0.00000 0.00000 0.00000" xyz="0.00000 0.00000 0.00000"/>
      <material name="Material.006"/>
      <geometry>
        <mesh filename="package://rs_robot_pkg2/meshes/stl/front_right_link.stl" scale="1.00000 1.00000 1.00000"/>
      </geometry>
    </visual>
  </link>
  <link name="fr_wheel_link">
    <collision name="fr_wheel_link_collision">
      <origin rpy="0.00000 0.00000 0.00000" xyz="0.00000 0.00000 0.00000"/>
      <geometry>
        <mesh filename="package://rs_robot_pkg2/meshes/stl/robot_wheel.stl" scale="1.00000 1.00000 1.00000"/>
      </geometry>
    </collision>
    <inertial>
      <inertia ixx="0.00001" ixy="0.00000" ixz="0.00000" iyy="0.00002" iyz="0.00000" izz="0.00001"/>
      <origin rpy="0.00000 0.00000 0.00000" xyz="0.00000 -0.00700 0.00000"/>
      <mass value="0.05000"/>
    </inertial>
    <visual name="fr_wheel_link_visual">
      <origin rpy="0.00000 0.00000 0.00000" xyz="0.00000 0.00000 0.00000"/>
      <material name="Material.018"/>
      <geometry>
        <mesh filename="package://rs_robot_pkg2/meshes/stl/wheel_link.stl" scale="1.00000 1.00000 1.00000"/>
      </geometry>
    </visual>
  </link>
  <link name="rl_steering_link">
    <collision name="rl_steering_link_collision">
      <origin rpy="0.00000 0.00000 0.00000" xyz="0.00000 0.00000 0.00000"/>
      <geometry>
        <mesh filename="package://rs_robot_pkg2/meshes/stl/sus_link.stl" scale="1.00000 1.00000 1.00000"/>
      </geometry>
    </collision>
    <inertial>
      <inertia ixx="0.00001" ixy="0.00000" ixz="0.00000" iyy="0.00001" iyz="0.00000" izz="0.00000"/>
      <origin rpy="0.00000 0.00000 0.00000" xyz="0.00000 0.00000 -0.02000"/>
      <mass value="0.15000"/>
    </inertial>
    <visual name="rl_steering_link_visual">
      <origin rpy="0.00000 0.00000 0.00000" xyz="0.00000 0.00000 0.00000"/>
      <material name="Material.015"/>
      <geometry>
        <mesh filename="package://rs_robot_pkg2/meshes/stl/rear_left_link.stl" scale="1.00000 1.00000 1.00000"/>
      </geometry>
    </visual>
  </link>
  <link name="rl_wheel_link">
    <collision name="rl_wheel_link_collision">
      <origin rpy="0.00000 0.00000 -0.00000" xyz="0.00000 0.00000 0.00000"/>
      <geometry>
        <mesh filename="package://rs_robot_pkg2/meshes/stl/robot_wheel.stl" scale="1.00000 1.00000 1.00000"/>
      </geometry>
    </collision>
    <inertial>
      <inertia ixx="0.00001" ixy="0.00000" ixz="0.00000" iyy="0.00002" iyz="0.00000" izz="0.00001"/>
      <origin rpy="0.00000 0.00000 0.00000" xyz="0.00000 -0.00700 0.00000"/>
      <mass value="0.05000"/>
    </inertial>
    <visual name="rl_wheel_link_visual">
      <origin rpy="0.00000 0.00000 -0.00000" xyz="0.00000 0.00000 0.00000"/>
      <material name="Material.018"/>
      <geometry>
        <mesh filename="package://rs_robot_pkg2/meshes/stl/wheel_link.stl" scale="1.00000 1.00000 1.00000"/>
      </geometry>
    </visual>
  </link>
  <link name="rr_steering_link">
    <collision name="rr_steering_link_collision">
      <origin rpy="0.00000 0.00000 0.00000" xyz="0.00000 0.00000 0.00000"/>
      <geometry>
        <mesh filename="package://rs_robot_pkg2/meshes/stl/sus_link.stl" scale="1.00000 1.00000 1.00000"/>
      </geometry>
    </collision>
    <inertial>
      <inertia ixx="0.00001" ixy="0.00000" ixz="0.00000" iyy="0.00001" iyz="0.00000" izz="0.00000"/>
      <origin rpy="0.00000 0.00000 0.00000" xyz="0.00000 0.00000 -0.02000"/>
      <mass value="0.15000"/>
    </inertial>
    <visual name="rr_steering_link_visual">
      <origin rpy="0.00000 0.00000 0.00000" xyz="0.00000 0.00000 0.00000"/>
      <material name="Material.012"/>
      <geometry>
        <mesh filename="package://rs_robot_pkg2/meshes/stl/rear_right_link.stl" scale="1.00000 1.00000 1.00000"/>
      </geometry>
    </visual>
  </link>
  <link name="rr_wheel_link">
    <collision name="rr_wheel_link_collision">
      <origin rpy="0.00000 0.00000 0.00000" xyz="0.00000 0.00000 0.00000"/>
      <geometry>
        <mesh filename="package://rs_robot_pkg2/meshes/stl/robot_wheel.stl" scale="1.00000 1.00000 1.00000"/>
      </geometry>
    </collision>
    <inertial>
      <inertia ixx="0.00001" ixy="0.00000" ixz="0.00000" iyy="0.00002" iyz="0.00000" izz="0.00001"/>
      <origin rpy="0.00000 0.00000 0.00000" xyz="0.00000 -0.00700 0.00000"/>
      <mass value="0.05000"/>
    </inertial>
    <visual name="rr_wheel_link_visual">
      <origin rpy="0.00000 0.00000 0.00000" xyz="0.00000 0.00000 0.00000"/>
      <material name="Material.018"/>
      <geometry>
        <mesh filename="package://rs_robot_pkg2/meshes/stl/wheel_link.stl" scale="1.00000 1.00000 1.00000"/>
      </geometry>
    </visual>
  </link>
  <material name="Material.001">
    <color rgba="0.80000 0.80000 0.80000 1.00000"/>
  </material>
  <material name="Material.006">
    <color rgba="0.09020 0.09020 0.09020 1.00000"/>
  </material>
  <material name="Material.009">
    <color rgba="0.09020 0.09020 0.09020 1.00000"/>
  </material>
  <material name="Material.012">
    <color rgba="0.80000 0.34902 0.12157 1.00000"/>
  </material>
  <material name="Material.015">
    <color rgba="0.09020 0.09020 0.09020 1.00000"/>
  </material>
  <material name="Material.018">
    <color rgba="0.04706 0.04706 0.04706 1.00000"/>
  </material>
</robot>